Workbook

Sheet Dashboard
A1: SALES ANALYTICS DASHBOARD
A3: 2025 | Synthetic practice dataset | Currency: INR
A4: Region Filter | B4: All | D4: Select a region in B4 to update KPI cards.
A6: TOTAL REVENUE | D6: TOTAL PROFIT | G6: TOTAL ORDERS | J6: PROFIT MARGIN
A7: =IF($B$4="All",SUM(Clean_Data!$P$2:$P$601),SUMIFS(Clean_Data!$P$2:$P$601,Clean_Data!$C$2:$C$601,$B$4)) | D7: =IF($B$4="All",SUM(Clean_Data!$Q$2:$Q$601),SUMIFS(Clean_Data!$Q$2:$Q$601,Clean_Data!$C$2:$C$601,$B$4)) | G7: =IF($B$4="All",COUNTA(Clean_Data!$A$2:$A$601),COUNTIF(Clean_Data!$C$2:$C$601,$B$4)) | J7: =IFERROR(IF($B$4="All",SUM(Clean_Data!$Q$2:$Q$601)/SUM(Clean_Data!$P$2:$P$601),SUMIFS(Clean_Data!$Q$2:$Q$601,Clean_Data!$C$2:$C$601,$B$4)/SUMIFS(Clean_Data!$P$2:$P$601,Clean_Data!$C$2:$C$601,$B$4)),0)
A42: Note: KPI cards respond to the region selector; charts show overall dataset summaries.

Sheet Raw_Data
A1: Order_ID | B1: Order_Date | C1: Region | D1: City | E1: Sales_Channel | F1: Customer_Segment | G1: Sales_Rep | H1: Product | I1: Category | J1: Quantity | K1: Unit_Price_INR | L1: Discount_Rate | M1: Revenue_INR | N1: Estimated_Cost_INR | O1: Profit_INR
A2: ORD-0001 | B2: 2025-11-24 | C2: South | D2: Chennai | E2: Online | F2: Corporate | G2: Priya Verma | H2: Wireless Mouse | I2: Accessories | J2: 1 | K2: 831.73 | L2: 0.15 | M2: 706.97 | N2: 565.58 | O2: 141.39
A3: ORD-0002 | B3: 2025-10-30 | C3: South | D3: Bengaluru | E3: Retail Store | F3: Corporate | G3: Vihaan Gupta | H3: Headphones | I3: Accessories | J3: 1 | K3: 2287.48 | L3: 0 | M3: 2287.48 | N3: 1601.24 | O3: 686.24
A4: ORD-0003 | B4: 2025-04-23 | C4: North | D4: Jaipur | E4: Marketplace | F4: Small Business | G4: Kabir Mehta | H4: Printer | I4: Electronics | J4: 10 | K4: 10322.54 | L4: 0.05 | M4: 98064.13 | N4: 86709.34 | O4: 11354.79
A5: ORD-0004 | B5: 2025-03-21 | C5: North | D5: Dehradun | E5: Corporate Sales | F5: Corporate | G5: Kabir Mehta | H5: Monitor | I5: Electronics | J5: 6 | K5: 11912.31 | L5: 0 | M5: 71473.86 | N5: 58608.57 | O5: 12865.29
A6: ORD-0005 | B6: 2025-01-23 | C6: West | D6: Mumbai | E6: Corporate Sales | F6: Corporate | G6: Isha Kapoor | H6: Printer | I6: Electronics | J6: 9 | K6: 10547.11 | L6: 0 | M6: 94923.99 | N6: 79736.15 | O6: 15187.84
A7: ORD-0006 | B7: 2025-10-23 | C7: South | D7: Hyderabad | E7: Online | F7: Consumer | G7: Priya Verma | H7: Monitor | I7: Electronics | J7: 12 | K7: 11830.19 | L7: 0 | M7: 141962.28 | N7: 116409.07 | O7: 25553.21
A8: ORD-0007 | B8: 2025-07-14 | C8: South | D8: Hyderabad | E8: Corporate Sales | F8: Consumer | G8: Kabir Mehta | H8: Office Chair | I8: Furniture | J8: 8 | K8: 8242.85 | L8: 0.15 | M8: 56051.38 | N8: 51435.38 | O8: 4616
A9: ORD-0008 | B9: 2025-12-26 | C9: South | D9: Chennai | E9: Marketplace | F9: Small Business | G9: Kabir Mehta | H9: Wireless Mouse | I9: Accessories | J9: 10 | K9: 819.37 | L9: 0.15 | M9: 6964.65 | N9: 5571.72 | O9: 1392.93
A10: ORD-0009 | B10: 2025-11-24 | C10: North | D10: Jaipur | E10: Online | F10: Small Business | G10: Vihaan Gupta | H10: Webcam | I10: Accessories | J10: 4 | K10: 3153.28 | L10: 0.15 | M10: 10721.15 | N10: 9459.84 | O10: 1261.31
A11: ORD-0010 | B11: 2025-05-18 | C11: East | D11: Patna | E11: Marketplace | F11: Small Business | G11: Sara Khan | H11: Wireless Mouse | I11: Accessories | J11: 4 | K11: 903.29 | L11: 0.1 | M11: 3251.84 | N11: 2456.95 | O11: 794.89
A12: ORD-0011 | B12: 2025-03-15 | C12: East | D12: Guwahati | E12: Marketplace | F12: Small Business | G12: Ananya Joshi | H12: Office Chair | I12: Furniture | J12: 3 | K12: 8145.53 | L12: 0.02 | M12: 23947.86 | N12: 19060.54 | O12: 4887.32
A13: ORD-0012 | B13: 2025-03-12 | C13: North | D13: Jaipur | E13: Retail Store | F13: Corporate | G13: Vihaan Gupta | H13: Webcam | I13: Accessories | J13: 8 | K13: 3346.59 | L13: 0 | M13: 26772.72 | N13: 20079.54 | O13: 6693.18
... A18: ORD-0017 | B18: 2025-01-30 | C18: West | D18: Mumbai | E18: Retail Store | F18: Consumer | G18: Sara Khan | H18: Monitor | I18: Electronics | J18: 10 | K18: 11899.89 | L18: 0 | M18: 118998.9 | N18: 97579.1 | O18: 21419.8
A19: ORD-0018 | B19: 2025-10-09 | C19: West | E19: Retail Store | F19: Corporate | G19: Kabir Mehta | H19: Keyboard | I19: Accessories | J19: 5 | K19: 1911.85 | L19: 0.1 | M19: 8603.33 | N19: 6882.66 | O19: 1720.67
A20: ORD-0019 | B20: 2025-07-24 | C20: South | D20: Chennai | E20: Online | F20: Small Business | G20: Aarav Sharma | H20: Desk | I20: Furniture | J20: 8 | K20: 6420.53 | L20: 0.1 | M20: 46227.82 | N20: 41091.39 | O20: 5136.43
A21: ORD-0020 | B21: 2025-10-29 | C21: North | D21: Delhi | E21: Retail Store | F21: Consumer | G21: Aarav Sharma | H21: Webcam | I21: Accessories | J21: 4 | K21: 3106.66 | L21: 0.1 | M21: 11183.98 | N21: 9319.98 | O21: 1864
A22: ORD-0021 | B22: 2025-06-19 | C22: West | D22: Pune | E22: Retail Store | F22: Corporate | G22: Sara Khan | H22: Wireless Mouse | I22: Accessories | J22: 9 | K22: 832.14 | L22: 0.02 | M22: 7339.47 | N22: 5092.7 | O22: 2246.77
A23: ORD-0022 | B23: 2025-05-05 | C23: West | D23: Ahmedabad | E23: Marketplace | F23: Small Business | G23: Sara Khan | H23: Printer | I23: Electronics | J23: 7 | K23: 9341.41 | L23: 0.02 | M23: 64082.07 | N23: 54927.49 | O23: 9154.58
A24: ORD-0023 | B24: 2025-01-28 | C24: North | D24: Jaipur | E24: Retail Store | F24: Consumer | G24: Sara Khan | H24: Wireless Mouse | I24: Accessories | J24: 1 | K24: 885.66 | L24: 0.08 | M24: 814.81 | N24: 602.25 | O24: 212.56
A25: ORD-0024 | B25: 2025-03-13 | C25: North | D25: Chandigarh | E25: Online | F25: Consumer | G25: Aarav Sharma | H25: Headphones | I25: Accessories | J25: 3 | K25: 2411.44 | L25: 0.05 | M25: 6872.6 | N25: 5064.02 | O25: 1808.58
A26: ORD-0025 | B26: 2025-02-17 | C26: South | D26: Kochi | E26: Online | F26: Consumer | G26: Vihaan Gupta | H26: Monitor | I26: Electronics | J26: 3 | K26: 12599.87 | L26: 0.08 | M26: 34775.64 | N26: 30995.68 | O26: 3779.96
A27: ORD-0026 | B27: 2025-01-02 | C27: West | D27: Pune | E27: Retail Store | F27: Small Business | G27: Ananya Joshi | H27: Headphones | I27: Accessories | J27: 5 | K27: 2351.84 | L27: 0.08 | M27: 10818.46 | N27: 8231.44 | O27: 2587.02
A28: ORD-0027 | B28: 2025-01-30 | C28: East | D28: Kolkata | E28: Online | F28: Corporate | G28: Sara Khan | H28: External SSD | I28: Electronics | J28: 12 | K28: 5880.91 | L28: 0.1 | M28: 63513.83 | N28: 55751.03 | O28: 7762.8
A29: ORD-0028 | B29: 2025-09-15 | C29: North | D29: Jaipur | E29: Online | F29: Corporate | G29: Priya Verma | H29: Webcam | I29: Accessories | J29: 3 | K29: 3438.43 | L29: 0 | M29: 10315.29 | N29: 7736.47 | O29: 2578.82
A30: ORD-0029 | B30: 2025-12-12 | C30: South | D30: Bengaluru | E30: Online | F30: Small Business | G30: Isha Kapoor | H30: Monitor | I30: Electronics | J30: 7 | K30: 13397.79 | L30: 0 | M30: 93784.53 | N30: 76903.31 | O30: 16881.22
A31: ORD-0030 | B31: 2025-05-14 | C31: East | D31: Guwahati | E31: Retail Store | F31: Corporate | G31: Kabir Mehta | H31: Monitor | I31: Electronics | J31: 11 | K31: 12299.82 | L31: 0.15 | M31: 115003.32 | N31: 110944.38 | O31: 4058.94
... A104: ORD-0103 | B104: 2025-06-16 | C104: South | D104: Chennai | E104: Marketplace | F104: Corporate | G104: Rohan Singh | H104: Laptop | I104: Electronics | J104: 5 | K104: 51608.84 | L104: 0.05 | M104: 245141.99 | N104: 219337.57 | O104: 25804.42
A105: ORD-0104 | B105: 2025-03-29 | C105: South | E105: Retail Store | F105: Consumer | G105: Sara Khan | H105: Keyboard | I105: Accessories | J105: 2 | K105: 1911.45 | L105: 0.1 | M105: 3440.61 | N105: 2752.49 | O105: 688.12
A106: ORD-0105 | B106: 2025-11-23 | C106: West | D106: Ahmedabad | E106: Retail Store | F106: Consumer | G106: Sara Khan | H106: Office Chair | I106: Furniture | J106: 8 | K106: 8060.19 | L106: 0.05 | M106: 61257.44 | N106: 50295.59 | O106: 10961.85
A107: ORD-0106 | B107: 2025-06-26 | C107: East | D107: Guwahati | E107: Corporate Sales | F107: Consumer | G107: Vihaan Gupta | H107: External SSD | I107: Electronics | J107: 5 | K107: 6663.04 | L107: 0.15 | M107: 28317.92 | N107: 26319.01 | O107: 1998.91
A108: ORD-0107 | B108: 2025-09-05 | C108: East | D108: Bhubaneswar | E108: Online | F108: Corporate | G108: Vihaan Gupta | H108: Wireless Mouse | I108: Accessories | J108: 4 | K108: 867.06 | L108: 0.08 | M108: 3190.78 | N108: 2358.4 | O108: 832.38
A109: ORD-0108 | B109: 2025-05-21 | C109: North | D109: Chandigarh | E109: Corporate Sales | F109: Consumer | G109: Isha Kapoor | H109: Laptop | I109: Electronics | J109: 10 | K109: 54546.11 | L109: 0.15 | M109: 463641.93 | N109: 463641.93 | O109: 0
A110: ORD-0109 | B110: 2025-04-23 | C110: South | D110: Bengaluru | E110: Online | F110: Small Business | G110: Sara Khan | H110: Monitor | I110: Electronics | J110: 10 | K110: 12936.09 | L110: 0.05 | M110: 122892.85 | N110: 106075.94 | O110: 16816.91
A111: ORD-0110 | B111: 2025-01-18 | C111: East | D111: Bhubaneswar | E111: Marketplace | F111: Consumer | G111: Ananya Joshi | H111: External SSD | I111: Electronics | J111: 6 | K111: 5942.07 | L111: 0.15 | M111: 30304.56 | N111: 28165.41 | O111: 2139.15
A112: ORD-0111 | B112: 2025-03-09 | C112: East | D112: Patna | E112: Corporate Sales | F112: Small Business | G112: Kabir Mehta | H112: Webcam | I112: Accessories | J112: 6 | K112: 3232.8 | L112: 0.1 | M112: 17457.12 | N112: 14547.6 | O112: 2909.52
A113: ORD-0112 | B113: 2025-06-23 | C113: South | D113: Kochi | E113: Corporate Sales | F113: Consumer | G113: Vihaan Gupta | H113: Wireless Mouse | I113: Accessories | J113: 8 | K113: 815.75 | L113: 0 | M113: 6526 | N113: 4437.68 | O113: 2088.32
A114: ORD-0113 | B114: 2025-01-08 | C114: East | D114: Guwahati | E114: Corporate Sales | F114: Consumer | G114: Ananya Joshi | H114: Office Chair | I114: Furniture | J114: 9 | K114: 7828.63 | L114: 0 | M114: 70457.67 | N114: 54956.98 | O114: 15500.69
A115: ORD-0114 | B115: 2025-08-30 | C115: South | D115: Bengaluru | E115: Marketplace | F115: Corporate | G115: Kabir Mehta | H115: Laptop | I115: Electronics | J115: 10 | K115: 51267.89 | L115: 0.1 | M115: 461411.01 | N115: 435777.07 | O115: 25633.94
A116: ORD-0115 | B116: 2025-11-29 | C116: North | D116: Dehradun | E116: Marketplace | F116: Consumer | G116: Priya Verma | H116: Headphones | I116: Accessories | J116: 2 | K116: 2271.24 | L116: 0.02 | M116: 4451.63 | N116: 3179.74 | O116: 1271.89
...

Sheet Clean_Data
A1: Order_ID | B1: Order_Date | C1: Region | D1: City | E1: Sales_Channel | F1: Customer_Segment | G1: Sales_Rep | H1: Product | I1: Category | J1: Quantity | K1: Unit_Price_INR | L1: Discount_Rate | M1: Revenue_INR | N1: Estimated_Cost_INR | O1: Profit_INR | P1: Calculated_Revenue | Q1: Calculated_Profit | R1: Profit_Margin | S1: Order_Month
A2: ORD-0001 | B2: 45985 | C2: South | D2: Chennai | E2: Online | F2: Corporate | G2: Priya Verma | H2: Wireless Mouse | I2: Accessories | J2: 1 | K2: 831.73 | L2: 0.15 | M2: 706.97 | N2: 565.58 | O2: 141.39 | P2: 706.97 | Q2: 141.39 | R2: 0.19999434 | S2: Nov-2025
A3: ORD-0002 | B3: 45960 | C3: South | D3: Bengaluru | E3: Retail Store | F3: Corporate | G3: Vihaan Gupta | H3: Headphones | I3: Accessories | J3: 1 | K3: 2287.48 | L3: 0 | M3: 2287.48 | N3: 1601.24 | O3: 686.24 | P3: 2287.48 | Q3: 686.24 | R3: 0.29999825 | S3: Oct-2025
A4: ORD-0003 | B4: 45770 | C4: North | D4: Jaipur | E4: Marketplace | F4: Small Business | G4: Kabir Mehta | H4: Printer | I4: Electronics | J4: 10 | K4: 10322.54 | L4: 0.05 | M4: 98064.13 | N4: 86709.34 | O4: 11354.79 | P4: 98064.13 | Q4: 11354.79 | R4: 0.11578943 | S4: Apr-2025
A5: ORD-0004 | B5: 45737 | C5: North | D5: Dehradun | E5: Corporate Sales | F5: Corporate | G5: Kabir Mehta | H5: Monitor | I5: Electronics | J5: 6 | K5: 11912.31 | L5: 0 | M5: 71473.86 | N5: 58608.57 | O5: 12865.29 | P5: 71473.86 | Q5: 12865.29 | R5: 0.17999993 | S5: Mar-2025
A6: ORD-0005 | B6: 45680 | C6: West | D6: Mumbai | E6: Corporate Sales | F6: Corporate | G6: Isha Kapoor | H6: Printer | I6: Electronics | J6: 9 | K6: 10547.11 | L6: 0 | M6: 94923.99 | N6: 79736.15 | O6: 15187.84 | P6: 94923.99 | Q6: 15187.84 | R6: 0.16000002 | S6: Jan-2025
A7: ORD-0006 | B7: 45953 | C7: South | D7: Hyderabad | E7: Online | F7: Consumer | G7: Priya Verma | H7: Monitor | I7: Electronics | J7: 12 | K7: 11830.19 | L7: 0 | M7: 141962.28 | N7: 116409.07 | O7: 25553.21 | P7: 141962.28 | Q7: 25553.21 | R7: 0.18 | S7: Oct-2025
A8: ORD-0007 | B8: 45852 | C8: South | D8: Hyderabad | E8: Corporate Sales | F8: Consumer | G8: Kabir Mehta | H8: Office Chair | I8: Furniture | J8: 8 | K8: 8242.85 | L8: 0.15 | M8: 56051.38 | N8: 51435.38 | O8: 4616 | P8: 56051.38 | Q8: 4616 | R8: 0.082353013 | S8: Jul-2025
A9: ORD-0008 | B9: 46017 | C9: South | D9: Chennai | E9: Marketplace | F9: Small Business | G9: Kabir Mehta | H9: Wireless Mouse | I9: Accessories | J9: 10 | K9: 819.37 | L9: 0.15 | M9: 6964.65 | N9: 5571.72 | O9: 1392.93 | P9: 6964.64 | Q9: 1392.92 | R9: 0.19999885 | S9: Dec-2025
A10: ORD-0009 | B10: 45985 | C10: North | D10: Jaipur | E10: Online | F10: Small Business | G10: Vihaan Gupta | H10: Webcam | I10: Accessories | J10: 4 | K10: 3153.28 | L10: 0.15 | M10: 10721.15 | N10: 9459.84 | O10: 1261.31 | P10: 10721.15 | Q10: 1261.31 | R10: 0.11764689 | S10: Nov-2025
A11: ORD-0010 | B11: 45795 | C11: East | D11: Patna | E11: Marketplace | F11: Small Business | G11: Sara Khan | H11: Wireless Mouse | I11: Accessories | J11: 4 | K11: 903.29 | L11: 0.1 | M11: 3251.84 | N11: 2456.95 | O11: 794.89 | P11: 3251.84 | Q11: 794.89 | R11: 0.24444315 | S11: May-2025
A12: ORD-0011 | B12: 45731 | C12: East | D12: Guwahati | E12: Marketplace | F12: Small Business | G12: Ananya Joshi | H12: Office Chair | I12: Furniture | J12: 3 | K12: 8145.53 | L12: 0.02 | M12: 23947.86 | N12: 19060.54 | O12: 4887.32 | P12: 23947.86 | Q12: 4887.32 | R12: 0.2040817 | S12: Mar-2025
A13: ORD-0012 | B13: 45728 | C13: North | D13: Jaipur | E13: Retail Store | F13: Corporate | G13: Vihaan Gupta | H13: Webcam | I13: Accessories | J13: 8 | K13: 3346.59 | L13: 0 | M13: 26772.72 | N13: 20079.54 | O13: 6693.18 | P13: 26772.72 | Q13: 6693.18 | R13: 0.25 | S13: Mar-2025
... A601: ORD-0600 | B601: 45799 | C601: East | D601: Patna | E601: Retail Store | F601: Small Business | G601: Priya Verma | H601: Webcam | I601: Accessories | J601: 6 | K601: 3308.66 | L601: 0.08 | M601: 18263.8 | N601: 14888.97 | O601: 3374.83 | P601: 18263.8 | Q601: 3374.83 | R601: 0.18478247 | S601: May-2025

Sheet Analysis
A1: SALES ANALYSIS | SUMMARY TABLES
A3: Month | B3: Revenue (INR) | C3: Profit (INR) | E3: Region | F3: Revenue (INR) | G3: Profit (INR)
A4: 45658 | B4: =SUMIFS(Clean_Data!$P$2:$P$601,Clean_Data!$B$2:$B$601,">="&A4,Clean_Data!$B$2:$B$601,"<"&EDATE(A4,1)) | C4: =SUMIFS(Clean_Data!$Q$2:$Q$601,Clean_Data!$B$2:$B$601,">="&A4,Clean_Data!$B$2:$B$601,"<"&EDATE(A4,1)) | E4: North | F4: =SUMIFS(Clean_Data!$P$2:$P$601,Clean_Data!$C$2:$C$601,E4) | G4: =SUMIFS(Clean_Data!$Q$2:$Q$601,Clean_Data!$C$2:$C$601,E4)
A5: 45689 | B5: =SUMIFS(Clean_Data!$P$2:$P$601,Clean_Data!$B$2:$B$601,">="&A5,Clean_Data!$B$2:$B$601,"<"&EDATE(A5,1)) | C5: =SUMIFS(Clean_Data!$Q$2:$Q$601,Clean_Data!$B$2:$B$601,">="&A5,Clean_Data!$B$2:$B$601,"<"&EDATE(A5,1)) | E5: South | F5: =SUMIFS(Clean_Data!$P$2:$P$601,Clean_Data!$C$2:$C$601,E5) | G5: =SUMIFS(Clean_Data!$Q$2:$Q$601,Clean_Data!$C$2:$C$601,E5)
A6: 45717 | B6: =SUMIFS(Clean_Data!$P$2:$P$601,Clean_Data!$B$2:$B$601,">="&A6,Clean_Data!$B$2:$B$601,"<"&EDATE(A6,1)) | C6: =SUMIFS(Clean_Data!$Q$2:$Q$601,Clean_Data!$B$2:$B$601,">="&A6,Clean_Data!$B$2:$B$601,"<"&EDATE(A6,1)) | E6: East | F6: =SUMIFS(Clean_Data!$P$2:$P$601,Clean_Data!$C$2:$C$601,E6) | G6: =SUMIFS(Clean_Data!$Q$2:$Q$601,Clean_Data!$C$2:$C$601,E6)
A7: 45748 | B7: =SUMIFS(Clean_Data!$P$2:$P$601,Clean_Data!$B$2:$B$601,">="&A7,Clean_Data!$B$2:$B$601,"<"&EDATE(A7,1)) | C7: =SUMIFS(Clean_Data!$Q$2:$Q$601,Clean_Data!$B$2:$B$601,">="&A7,Clean_Data!$B$2:$B$601,"<"&EDATE(A7,1)) | E7: West | F7: =SUMIFS(Clean_Data!$P$2:$P$601,Clean_Data!$C$2:$C$601,E7) | G7: =SUMIFS(Clean_Data!$Q$2:$Q$601,Clean_Data!$C$2:$C$601,E7)
A8: 45778 | B8: =SUMIFS(Clean_Data!$P$2:$P$601,Clean_Data!$B$2:$B$601,">="&A8,Clean_Data!$B$2:$B$601,"<"&EDATE(A8,1)) | C8: =SUMIFS(Clean_Data!$Q$2:$Q$601,Clean_Data!$B$2:$B$601,">="&A8,Clean_Data!$B$2:$B$601,"<"&EDATE(A8,1))
A9: 45809 | B9: =SUMIFS(Clean_Data!$P$2:$P$601,Clean_Data!$B$2:$B$601,">="&A9,Clean_Data!$B$2:$B$601,"<"&EDATE(A9,1)) | C9: =SUMIFS(Clean_Data!$Q$2:$Q$601,Clean_Data!$B$2:$B$601,">="&A9,Clean_Data!$B$2:$B$601,"<"&EDATE(A9,1))
A10: 45839 | B10: =SUMIFS(Clean_Data!$P$2:$P$601,Clean_Data!$B$2:$B$601,">="&A10,Clean_Data!$B$2:$B$601,"<"&EDATE(A10,1)) | C10: =SUMIFS(Clean_Data!$Q$2:$Q$601,Clean_Data!$B$2:$B$601,">="&A10,Clean_Data!$B$2:$B$601,"<"&EDATE(A10,1))
A11: 45870 | B11: =SUMIFS(Clean_Data!$P$2:$P$601,Clean_Data!$B$2:$B$601,">="&A11,Clean_Data!$B$2:$B$601,"<"&EDATE(A11,1)) | C11: =SUMIFS(Clean_Data!$Q$2:$Q$601,Clean_Data!$B$2:$B$601,">="&A11,Clean_Data!$B$2:$B$601,"<"&EDATE(A11,1))
A12: 45901 | B12: =SUMIFS(Clean_Data!$P$2:$P$601,Clean_Data!$B$2:$B$601,">="&A12,Clean_Data!$B$2:$B$601,"<"&EDATE(A12,1)) | C12: =SUMIFS(Clean_Data!$Q$2:$Q$601,Clean_Data!$B$2:$B$601,">="&A12,Clean_Data!$B$2:$B$601,"<"&EDATE(A12,1))
A13: 45931 | B13: =SUMIFS(Clean_Data!$P$2:$P$601,Clean_Data!$B$2:$B$601,">="&A13,Clean_Data!$B$2:$B$601,"<"&EDATE(A13,1)) | C13: =SUMIFS(Clean_Data!$Q$2:$Q$601,Clean_Data!$B$2:$B$601,">="&A13,Clean_Data!$B$2:$B$601,"<"&EDATE(A13,1))
A14: 45962 | B14: =SUMIFS(Clean_Data!$P$2:$P$601,Clean_Data!$B$2:$B$601,">="&A14,Clean_Data!$B$2:$B$601,"<"&EDATE(A14,1)) | C14: =SUMIFS(Clean_Data!$Q$2:$Q$601,Clean_Data!$B$2:$B$601,">="&A14,Clean_Data!$B$2:$B$601,"<"&EDATE(A14,1))
A15: 45992 | B15: =SUMIFS(Clean_Data!$P$2:$P$601,Clean_Data!$B$2:$B$601,">="&A15,Clean_Data!$B$2:$B$601,"<"&EDATE(A15,1)) | C15: =SUMIFS(Clean_Data!$Q$2:$Q$601,Clean_Data!$B$2:$B$601,">="&A15,Clean_Data!$B$2:$B$601,"<"&EDATE(A15,1))
A19: Category | B19: Revenue (INR) | C19: Profit (INR) | E19: Product | F19: Revenue (INR) | G19: Profit (INR)
A20: Electronics | B20: =SUMIFS(Clean_Data!$P$2:$P$601,Clean_Data!$I$2:$I$601,A20) | C20: =SUMIFS(Clean_Data!$Q$2:$Q$601,Clean_Data!$I$2:$I$601,A20) | E20: Laptop | F20: =SUMIFS(Clean_Data!$P$2:$P$601,Clean_Data!$H$2:$H$601,E20) | G20: =SUMIFS(Clean_Data!$Q$2:$Q$601,Clean_Data!$H$2:$H$601,E20)
A21: Accessories | B21: =SUMIFS(Clean_Data!$P$2:$P$601,Clean_Data!$I$2:$I$601,A21) | C21: =SUMIFS(Clean_Data!$Q$2:$Q$601,Clean_Data!$I$2:$I$601,A21) | E21: Monitor | F21: =SUMIFS(Clean_Data!$P$2:$P$601,Clean_Data!$H$2:$H$601,E21) | G21: =SUMIFS(Clean_Data!$Q$2:$Q$601,Clean_Data!$H$2:$H$601,E21)
A22: Furniture | B22: =SUMIFS(Clean_Data!$P$2:$P$601,Clean_Data!$I$2:$I$601,A22) | C22: =SUMIFS(Clean_Data!$Q$2:$Q$601,Clean_Data!$I$2:$I$601,A22) | E22: Printer | F22: =SUMIFS(Clean_Data!$P$2:$P$601,Clean_Data!$H$2:$H$601,E22) | G22: =SUMIFS(Clean_Data!$Q$2:$Q$601,Clean_Data!$H$2:$H$601,E22)
E23: Office Chair | F23: =SUMIFS(Clean_Data!$P$2:$P$601,Clean_Data!$H$2:$H$601,E23) | G23: =SUMIFS(Clean_Data!$Q$2:$Q$601,Clean_Data!$H$2:$H$601,E23)
E24: External SSD | F24: =SUMIFS(Clean_Data!$P$2:$P$601,Clean_Data!$H$2:$H$601,E24) | G24: =SUMIFS(Clean_Data!$Q$2:$Q$601,Clean_Data!$H$2:$H$601,E24)
E25: Desk | F25: =SUMIFS(Clean_Data!$P$2:$P$601,Clean_Data!$H$2:$H$601,E25) | G25: =SUMIFS(Clean_Data!$Q$2:$Q$601,Clean_Data!$H$2:$H$601,E25)
E26: Webcam | F26: =SUMIFS(Clean_Data!$P$2:$P$601,Clean_Data!$H$2:$H$601,E26) | G26: =SUMIFS(Clean_Data!$Q$2:$Q$601,Clean_Data!$H$2:$H$601,E26)
E27: Keyboard | F27: =SUMIFS(Clean_Data!$P$2:$P$601,Clean_Data!$H$2:$H$601,E27) | G27: =SUMIFS(Clean_Data!$Q$2:$Q$601,Clean_Data!$H$2:$H$601,E27)
E28: Headphones | F28: =SUMIFS(Clean_Data!$P$2:$P$601,Clean_Data!$H$2:$H$601,E28) | G28: =SUMIFS(Clean_Data!$Q$2:$Q$601,Clean_Data!$H$2:$H$601,E28)
E29: Wireless Mouse | F29: =SUMIFS(Clean_Data!$P$2:$P$601,Clean_Data!$H$2:$H$601,E29) | G29: =SUMIFS(Clean_Data!$Q$2:$Q$601,Clean_Data!$H$2:$H$601,E29)

Sheet Data_Dictionary
A1: Column | B1: Meaning | C1: Expected_Format
A2: Order_ID | B2: Unique order identifier | C2: Text
A3: Order_Date | B3: Date the order was placed | C3: YYYY-MM-DD
A4: Region | B4: Sales region | C4: North/South/East/West
A5: City | B5: Customer city | C5: City within the selected region
A6: Sales_Channel | B6: Channel where sale occurred | C6: Online/Retail Store/Corporate Sales/Marketplace
A7: Customer_Segment | B7: Customer type | C7: Consumer/Small Business/Corporate
A8: Sales_Rep | B8: Employee responsible for the sale | C8: Name
A9: Product | B9: Product sold | C9: Product name
A10: Category | B10: Product category | C10: Electronics/Accessories/Furniture
A11: Quantity | B11: Units sold | C11: Whole number
A12: Unit_Price_INR | B12: Price per unit before discount | C12: INR
... A16: Profit_INR | B16: Revenue minus estimated cost | C16: INR

Sheet Start_Here
A1: PROJECT GUIDE | SALES ANALYTICS DASHBOARD
A4: Objective | B4: Analyze synthetic 2025 sales transactions to understand revenue, estimated profit, margin, region, category, and product performance.
A5: Dashboard | B5: Change Dashboard!B4 to All, North, South, East, or West to update KPI cards.
A6: Raw_Data | B6: Original imported dataset preserved for auditability.
A7: Clean_Data | B7: Missing City values labeled Unknown; text spaces trimmed; calculated metrics added.
A8: Analysis | B8: Formula-driven summary tables behind dashboard charts.
A9: Data_Dictionary | B9: Definitions for original data fields.
A10: Calculations | B10: Revenue = Quantity × Unit Price × (1 − Discount Rate); Profit = calculated revenue − estimated cost.
A11: Important | B11: Synthetic practice data only; estimated profit is not audited accounting profit.
A12: GitHub repo name | B12: excel-sales-analytics-dashboard
